Traceback (most recent call last):
  File "/Users/julieneg/opt/miniconda3/envs/jbook/lib/python3.12/site-packages/jupyter_cache/executors/utils.py", line 58, in single_nb_execution
    executenb(
  File "/Users/julieneg/opt/miniconda3/envs/jbook/lib/python3.12/site-packages/nbclient/client.py", line 1314, in execute
    return NotebookClient(nb=nb, resources=resources, km=km, **kwargs).execute()
           ^^^^^^^^^^^^^^^^^^^^^^^^^^^^^^^^^^^^^^^^^^^^^^^^^^^^^^^^^^^^^^^^^^^^^
  File "/Users/julieneg/opt/miniconda3/envs/jbook/lib/python3.12/site-packages/jupyter_core/utils/__init__.py", line 165, in wrapped
    return loop.run_until_complete(inner)
           ^^^^^^^^^^^^^^^^^^^^^^^^^^^^^^
  File "/Users/julieneg/opt/miniconda3/envs/jbook/lib/python3.12/asyncio/base_events.py", line 687, in run_until_complete
    return future.result()
           ^^^^^^^^^^^^^^^
  File "/Users/julieneg/opt/miniconda3/envs/jbook/lib/python3.12/site-packages/nbclient/client.py", line 709, in async_execute
    await self.async_execute_cell(
  File "/Users/julieneg/opt/miniconda3/envs/jbook/lib/python3.12/site-packages/nbclient/client.py", line 1062, in async_execute_cell
    await self._check_raise_for_error(cell, cell_index, exec_reply)
  File "/Users/julieneg/opt/miniconda3/envs/jbook/lib/python3.12/site-packages/nbclient/client.py", line 918, in _check_raise_for_error
    raise CellExecutionError.from_cell_and_msg(cell, exec_reply_content)
nbclient.exceptions.CellExecutionError: An error occurred while executing the following cell:
------------------
coh = nino3.wavelet_coherence(air)
fig, ax = coh.plot()
------------------


[0;31m---------------------------------------------------------------------------[0m
[0;31mAttributeError[0m                            Traceback (most recent call last)
Cell [0;32mIn[10], line 2[0m
[1;32m      1[0m coh [38;5;241m=[39m nino3[38;5;241m.[39mwavelet_coherence(air)
[0;32m----> 2[0m fig, ax [38;5;241m=[39m [43mcoh[49m[38;5;241;43m.[39;49m[43mplot[49m[43m([49m[43m)[49m

File [0;32m~/Documents/GitHub/Pyleoclim_util/pyleoclim/core/coherence.py:286[0m, in [0;36mCoherence.plot[0;34m(self, var, xlabel, ylabel, title, figsize, ylim, xlim, in_scale, yticks, contourf_style, phase_style, cbar_style, savefig_settings, ax, signif_clr, signif_linestyles, signif_linewidths, signif_thresh, under_clr, over_clr, bad_clr)[0m
[1;32m    280[0m contourf_args [38;5;241m=[39m {
[1;32m    281[0m     [38;5;124m'[39m[38;5;124mcmap[39m[38;5;124m'[39m: [38;5;124m'[39m[38;5;124mmagma[39m[38;5;124m'[39m,
[1;32m    282[0m     [38;5;124m'[39m[38;5;124morigin[39m[38;5;124m'[39m: [38;5;124m'[39m[38;5;124mlower[39m[38;5;124m'[39m,
[1;32m    283[0m }
[1;32m    284[0m contourf_args[38;5;241m.[39mupdate(contourf_style)
[0;32m--> 286[0m cmap [38;5;241m=[39m [43mcm[49m[38;5;241;43m.[39;49m[43mget_cmap[49m(contourf_args[[38;5;124m'[39m[38;5;124mcmap[39m[38;5;124m'[39m])
[1;32m    287[0m cmap[38;5;241m.[39mset_under(under_clr)
[1;32m    288[0m cmap[38;5;241m.[39mset_over(over_clr)

[0;31mAttributeError[0m: module 'matplotlib.cm' has no attribute 'get_cmap'

